<?xml version="1.0"?>
<robot xmlns:xacro="http://www.ros.org/wiki/xacro" name="tracked_rover_8wd">

  <xacro:property name="body_l" value="0.90"/>
  <xacro:property name="body_w" value="0.55"/>
  <xacro:property name="body_h" value="0.18"/>
  <xacro:property name="wheel_radius" value="0.055"/>
  <xacro:property name="wheel_width"  value="0.04"/>
  <xacro:property name="side_y" value="0.32"/>
  <xacro:property name="body_z"  value="0.16"/>
  <xacro:property name="wheel_z" value="${wheel_radius}"/> 
  <xacro:property name="plate_z" value="0.12"/>

  <link name="base_footprint"/>

  <joint name="base_footprint_joint" type="fixed">
    <parent link="base_footprint"/>
    <child link="base_link"/>
    <origin xyz="0 0 0" rpy="0 0 0"/>
  </joint>

  <link name="base_link">
    <visual>
      <origin xyz="0 0 ${body_z}" rpy="0 0 0"/>
      <geometry> <box size="${body_l} ${body_w} ${body_h}"/> </geometry>
      <material name="metal"> <color rgba="0.7 0.7 0.75 1"/> </material>
    </visual>
    <collision>
      <origin xyz="0 0 ${body_z}" rpy="0 0 0"/>
      <geometry> <box size="${body_l} ${body_w} ${body_h}"/> </geometry>
    </collision>
    <inertial>
      <origin xyz="0 0 ${body_z}" rpy="0 0 0"/>
      <mass value="30"/>
      <inertia ixx="1.2" iyy="1.8" izz="2.0" ixy="0" ixz="0" iyz="0"/>
    </inertial>
  </link>

  <xacro:macro name="track_body" params="name y_offset">
    <link name="${name}">
      <visual>
        <origin xyz="0 0 ${body_z}" rpy="0 0 0"/>
        <geometry> <box size="0.90 0.08 0.25"/> </geometry>
        <material name="dark"> <color rgba="0.2 0.2 0.2 1"/> </material>
      </visual>
      <collision> <origin xyz="0 0 ${body_z}" rpy="0 0 0"/>
        <geometry> <box size="0.90 0.08 0.25"/> </geometry>
      </collision>
      <inertial>
        <mass value="1.0"/>
        <inertia ixx="0.01" iyy="0.01" izz="0.01" ixy="0" ixz="0" iyz="0"/>
      </inertial>
    </link>
    <joint name="${name}_joint" type="fixed">
      <parent link="base_link"/>
      <child link="${name}"/>
      <origin xyz="0 ${y_offset} 0" rpy="0 0 0"/>
    </joint>
  </xacro:macro>

  <xacro:track_body name="left_track_body" y_offset="${side_y}"/>
  <xacro:track_body name="right_track_body" y_offset="-${side_y}"/>

  <xacro:macro name="road_wheel" params="name x y">
    <link name="${name}">
      <visual>
        <origin xyz="0 0 0" rpy="1.5708 0 0"/>
        <geometry> <cylinder radius="${wheel_radius}" length="${wheel_width}"/> </geometry>
        <material name="wheel"> <color rgba="0.3 0.3 0.3 1"/> </material>
      </visual>
      <collision>
        <origin xyz="0 0 0" rpy="1.5708 0 0"/>
        <geometry> <cylinder radius="${wheel_radius}" length="${wheel_width}"/> </geometry>
      </collision>
      <inertial>
        <mass value="0.8"/>
        <inertia ixx="0.001" iyy="0.001" izz="0.001" ixy="0" ixz="0" iyz="0"/>
      </inertial>
    </link>

    <joint name="${name}_joint" type="continuous">
      <parent link="base_link"/>
      <child link="${name}"/>
      <origin xyz="${x} ${y} ${wheel_z}" rpy="0 0 0"/>
      <axis xyz="0 1 0"/>
    </joint>

    <gazebo reference="${name}">
      <mu1>2.0</mu1>
      <mu2>2.0</mu2>
      <material>Gazebo/DarkGrey</material>
    </gazebo>
  </xacro:macro>

  <xacro:road_wheel name="lw1" x="0.35"  y="${side_y}"/>
  <xacro:road_wheel name="lw2" x="0.12"  y="${side_y}"/>
  <xacro:road_wheel name="lw3" x="-0.12" y="${side_y}"/>
  <xacro:road_wheel name="lw4" x="-0.35" y="${side_y}"/>

  <xacro:road_wheel name="rw1" x="0.35"  y="-${side_y}"/>
  <xacro:road_wheel name="rw2" x="0.12"  y="-${side_y}"/>
  <xacro:road_wheel name="rw3" x="-0.12" y="-${side_y}"/>
  <xacro:road_wheel name="rw4" x="-0.35" y="-${side_y}"/>

  <gazebo>
    <plugin name="diff_drive" filename="libgazebo_ros_diff_drive.so">
      <ros>
        <namespace>/</namespace>
      </ros>
      <update_rate>30</update_rate>
      <num_wheel_pairs>4</num_wheel_pairs>

      <left_joint>lw1_joint</left_joint>
      <left_joint>lw2_joint</left_joint>
      <left_joint>lw3_joint</left_joint>
      <left_joint>lw4_joint</left_joint>

      <right_joint>rw1_joint</right_joint>
      <right_joint>rw2_joint</right_joint>
      <right_joint>rw3_joint</right_joint>
      <right_joint>rw4_joint</right_joint>

      <wheel_separation>${side_y * 2}</wheel_separation>
      <wheel_diameter>${wheel_radius * 2}</wheel_diameter>
      
      <max_wheel_torque>20</max_wheel_torque>
      <max_wheel_acceleration>1.0</max_wheel_acceleration>

      <publish_odom>true</publish_odom>
      <publish_odom_tf>true</publish_odom_tf>
      <publish_wheel_tf>true</publish_wheel_tf>

      <odometry_frame>odom</odometry_frame>
      <robot_base_frame>base_footprint</robot_base_frame>
    </plugin>
  </gazebo>

</robot>
